Traceback (most recent call last):
  File "/home/petri/venv/python3/lib/python3.9/site-packages/jupyter_cache/executors/utils.py", line 51, in single_nb_execution
    executenb(
  File "/home/petri/venv/python3/lib/python3.9/site-packages/nbclient/client.py", line 1117, in execute
    return NotebookClient(nb=nb, resources=resources, km=km, **kwargs).execute()
  File "/home/petri/venv/python3/lib/python3.9/site-packages/nbclient/util.py", line 78, in wrapped
    return just_run(coro(*args, **kwargs))
  File "/home/petri/venv/python3/lib/python3.9/site-packages/nbclient/util.py", line 57, in just_run
    return loop.run_until_complete(coro)
  File "/usr/lib/python3.9/asyncio/base_events.py", line 642, in run_until_complete
    return future.result()
  File "/home/petri/venv/python3/lib/python3.9/site-packages/nbclient/client.py", line 558, in async_execute
    await self.async_execute_cell(
  File "/home/petri/venv/python3/lib/python3.9/site-packages/nbclient/client.py", line 862, in async_execute_cell
    self._check_raise_for_error(cell, exec_reply)
  File "/home/petri/venv/python3/lib/python3.9/site-packages/nbclient/client.py", line 765, in _check_raise_for_error
    raise CellExecutionError.from_cell_and_msg(cell, exec_reply_content)
nbclient.exceptions.CellExecutionError: An error occurred while executing the following cell:
------------------
pd.plotting.scatter_matrix(D, figsize=(15,15), marker='o');
------------------

[0;31m---------------------------------------------------------------------------[0m
[0;31mNameError[0m                                 Traceback (most recent call last)
[0;32m/tmp/ipykernel_21325/3413777684.py[0m in [0;36m<module>[0;34m[0m
[0;32m----> 1[0;31m [0mpd[0m[0;34m.[0m[0mplotting[0m[0;34m.[0m[0mscatter_matrix[0m[0;34m([0m[0mD[0m[0;34m,[0m [0mfigsize[0m[0;34m=[0m[0;34m([0m[0;36m15[0m[0;34m,[0m[0;36m15[0m[0;34m)[0m[0;34m,[0m [0mmarker[0m[0;34m=[0m[0;34m'o'[0m[0;34m)[0m[0;34m;[0m[0;34m[0m[0;34m[0m[0m
[0m
[0;31mNameError[0m: name 'D' is not defined
NameError: name 'D' is not defined

